<?xml version="1.0" ?>
<!-- =================================================================================== -->
<!-- |    This document was autogenerated by xacro from luna.xacro                     | -->
<!-- |    EDITING THIS FILE BY HAND IS NOT RECOMMENDED                                 | -->
<!-- =================================================================================== -->
<robot name="quadruped">
  <!-- Leg thickness -->
  <!-- Base link -->
  <link name="base_link">
    <inertial>
      <origin xyz="0 0 0"/>
      <mass value="7.0"/>
      <inertia ixx="0.1" ixy="0.0" ixz="0.0" iyy="0.1" iyz="0.0" izz="0.1"/>
    </inertial>
    <visual>
      <geometry>
        <box size="0.4 0.2 0.1"/>
        <!-- Base size: 40cm x 20cm x 10cm -->
      </geometry>
      <material name="blue"/>
    </visual>
    <collision>
      <geometry>
        <box size="0.4 0.2 0.1"/>
      </geometry>
    </collision>
  </link>
  <!-- Hip joint -->
  <joint name="FL_hip_joint" type="continuous">
    <parent link="base_link"/>
    <child link="FL_upper_leg"/>
    <origin rpy="0 0 0" xyz="0.2 0.1 0"/>
    <axis xyz="0 1 0"/>
    <limit effort="20" lower="-1.57" upper="1.57" velocity="2.0"/>
  </joint>
  <!-- Upper leg -->
  <link name="FL_upper_leg">
    <inertial>
      <origin xyz="0 0 -0.1"/>
      <mass value="1.0"/>
      <inertia ixx="0.01" ixy="0.0" ixz="0.0" iyy="0.01" iyz="0.0" izz="0.01"/>
    </inertial>
    <visual>
      <geometry>
        <cylinder length="0.2" radius="0.03"/>
      </geometry>
      <material name="black"/>
    </visual>
    <collision>
      <geometry>
        <cylinder length="0.2" radius="0.03"/>
      </geometry>
    </collision>
  </link>
  <!-- Knee joint -->
  <joint name="FL_knee_joint" type="continuous">
    <parent link="FL_upper_leg"/>
    <child link="FL_lower_leg"/>
    <origin rpy="0 0 0" xyz="0 0 -0.2"/>
    <axis xyz="0 1 0"/>
    <limit effort="20" lower="-1.57" upper="0" velocity="2.0"/>
  </joint>
  <!-- Lower leg -->
  <link name="FL_lower_leg">
    <inertial>
      <origin xyz="0 0 -0.15"/>
      <mass value="1.0"/>
      <inertia ixx="0.01" ixy="0.0" ixz="0.0" iyy="0.01" iyz="0.0" izz="0.01"/>
    </inertial>
    <visual>
      <geometry>
        <cylinder length="0.3" radius="0.03"/>
      </geometry>
      <material name="grey"/>
    </visual>
    <collision>
      <geometry>
        <cylinder length="0.3" radius="0.03"/>
      </geometry>
    </collision>
  </link>
  <!-- Ankle joint -->
  <joint name="FL_ankle_joint" type="continuous">
    <parent link="FL_lower_leg"/>
    <child link="FL_foot"/>
    <origin rpy="0 0 0" xyz="0 0 -0.3"/>
    <axis xyz="1 0 0"/>
    <limit effort="20" lower="-0.785" upper="0.785" velocity="2.0"/>
  </joint>
  <!-- Foot -->
  <link name="FL_foot">
    <inertial>
      <origin xyz="0 0 -0.05"/>
      <mass value="0.5"/>
      <inertia ixx="0.01" ixy="0.0" ixz="0.0" iyy="0.01" iyz="0.0" izz="0.01"/>
    </inertial>
    <visual>
      <geometry>
        <box size="0.1 0.05 0.02"/>
      </geometry>
      <material name="black"/>
    </visual>
    <collision>
      <geometry>
        <box size="0.1 0.05 0.02"/>
      </geometry>
    </collision>
  </link>
  <!-- Hip joint -->
  <joint name="FR_hip_joint" type="continuous">
    <parent link="base_link"/>
    <child link="FR_upper_leg"/>
    <origin rpy="0 0 0" xyz="0.2 -0.1 0"/>
    <axis xyz="0 1 0"/>
    <limit effort="20" lower="-1.57" upper="1.57" velocity="2.0"/>
  </joint>
  <!-- Upper leg -->
  <link name="FR_upper_leg">
    <inertial>
      <origin xyz="0 0 -0.1"/>
      <mass value="1.0"/>
      <inertia ixx="0.01" ixy="0.0" ixz="0.0" iyy="0.01" iyz="0.0" izz="0.01"/>
    </inertial>
    <visual>
      <geometry>
        <cylinder length="0.2" radius="0.03"/>
      </geometry>
      <material name="black"/>
    </visual>
    <collision>
      <geometry>
        <cylinder length="0.2" radius="0.03"/>
      </geometry>
    </collision>
  </link>
  <!-- Knee joint -->
  <joint name="FR_knee_joint" type="continuous">
    <parent link="FR_upper_leg"/>
    <child link="FR_lower_leg"/>
    <origin rpy="0 0 0" xyz="0 0 -0.2"/>
    <axis xyz="0 1 0"/>
    <limit effort="20" lower="-1.57" upper="0" velocity="2.0"/>
  </joint>
  <!-- Lower leg -->
  <link name="FR_lower_leg">
    <inertial>
      <origin xyz="0 0 -0.15"/>
      <mass value="1.0"/>
      <inertia ixx="0.01" ixy="0.0" ixz="0.0" iyy="0.01" iyz="0.0" izz="0.01"/>
    </inertial>
    <visual>
      <geometry>
        <cylinder length="0.3" radius="0.03"/>
      </geometry>
      <material name="grey"/>
    </visual>
    <collision>
      <geometry>
        <cylinder length="0.3" radius="0.03"/>
      </geometry>
    </collision>
  </link>
  <!-- Ankle joint -->
  <joint name="FR_ankle_joint" type="continuous">
    <parent link="FR_lower_leg"/>
    <child link="FR_foot"/>
    <origin rpy="0 0 0" xyz="0 0 -0.3"/>
    <axis xyz="1 0 0"/>
    <limit effort="20" lower="-0.785" upper="0.785" velocity="2.0"/>
  </joint>
  <!-- Foot -->
  <link name="FR_foot">
    <inertial>
      <origin xyz="0 0 -0.05"/>
      <mass value="0.5"/>
      <inertia ixx="0.01" ixy="0.0" ixz="0.0" iyy="0.01" iyz="0.0" izz="0.01"/>
    </inertial>
    <visual>
      <geometry>
        <box size="0.1 0.05 0.02"/>
      </geometry>
      <material name="black"/>
    </visual>
    <collision>
      <geometry>
        <box size="0.1 0.05 0.02"/>
      </geometry>
    </collision>
  </link>
  <!-- Hip joint -->
  <joint name="BL_hip_joint" type="continuous">
    <parent link="base_link"/>
    <child link="BL_upper_leg"/>
    <origin rpy="0 0 0" xyz="-0.2 0.1 0"/>
    <axis xyz="0 1 0"/>
    <limit effort="20" lower="-1.57" upper="1.57" velocity="2.0"/>
  </joint>
  <!-- Upper leg -->
  <link name="BL_upper_leg">
    <inertial>
      <origin xyz="0 0 -0.1"/>
      <mass value="1.0"/>
      <inertia ixx="0.01" ixy="0.0" ixz="0.0" iyy="0.01" iyz="0.0" izz="0.01"/>
    </inertial>
    <visual>
      <geometry>
        <cylinder length="0.2" radius="0.03"/>
      </geometry>
      <material name="black"/>
    </visual>
    <collision>
      <geometry>
        <cylinder length="0.2" radius="0.03"/>
      </geometry>
    </collision>
  </link>
  <!-- Knee joint -->
  <joint name="BL_knee_joint" type="continuous">
    <parent link="BL_upper_leg"/>
    <child link="BL_lower_leg"/>
    <origin rpy="0 0 0" xyz="0 0 -0.2"/>
    <axis xyz="0 1 0"/>
    <limit effort="20" lower="-1.57" upper="0" velocity="2.0"/>
  </joint>
  <!-- Lower leg -->
  <link name="BL_lower_leg">
    <inertial>
      <origin xyz="0 0 -0.15"/>
      <mass value="1.0"/>
      <inertia ixx="0.01" ixy="0.0" ixz="0.0" iyy="0.01" iyz="0.0" izz="0.01"/>
    </inertial>
    <visual>
      <geometry>
        <cylinder length="0.3" radius="0.03"/>
      </geometry>
      <material name="grey"/>
    </visual>
    <collision>
      <geometry>
        <cylinder length="0.3" radius="0.03"/>
      </geometry>
    </collision>
  </link>
  <!-- Ankle joint -->
  <joint name="BL_ankle_joint" type="continuous">
    <parent link="BL_lower_leg"/>
    <child link="BL_foot"/>
    <origin rpy="0 0 0" xyz="0 0 -0.3"/>
    <axis xyz="1 0 0"/>
    <limit effort="20" lower="-0.785" upper="0.785" velocity="2.0"/>
  </joint>
  <!-- Foot -->
  <link name="BL_foot">
    <inertial>
      <origin xyz="0 0 -0.05"/>
      <mass value="0.5"/>
      <inertia ixx="0.01" ixy="0.0" ixz="0.0" iyy="0.01" iyz="0.0" izz="0.01"/>
    </inertial>
    <visual>
      <geometry>
        <box size="0.1 0.05 0.02"/>
      </geometry>
      <material name="black"/>
    </visual>
    <collision>
      <geometry>
        <box size="0.1 0.05 0.02"/>
      </geometry>
    </collision>
  </link>
  <!-- Hip joint -->
  <joint name="BR_hip_joint" type="continuous">
    <parent link="base_link"/>
    <child link="BR_upper_leg"/>
    <origin rpy="0 0 0" xyz="-0.2 -0.1 0"/>
    <axis xyz="0 1 0"/>
    <limit effort="20" lower="-1.57" upper="1.57" velocity="2.0"/>
  </joint>
  <!-- Upper leg -->
  <link name="BR_upper_leg">
    <inertial>
      <origin xyz="0 0 -0.1"/>
      <mass value="1.0"/>
      <inertia ixx="0.01" ixy="0.0" ixz="0.0" iyy="0.01" iyz="0.0" izz="0.01"/>
    </inertial>
    <visual>
      <geometry>
        <cylinder length="0.2" radius="0.03"/>
      </geometry>
      <material name="black"/>
    </visual>
    <collision>
      <geometry>
        <cylinder length="0.2" radius="0.03"/>
      </geometry>
    </collision>
  </link>
  <!-- Knee joint -->
  <joint name="BR_knee_joint" type="continuous">
    <parent link="BR_upper_leg"/>
    <child link="BR_lower_leg"/>
    <origin rpy="0 0 0" xyz="0 0 -0.2"/>
    <axis xyz="0 1 0"/>
    <limit effort="20" lower="-1.57" upper="0" velocity="2.0"/>
  </joint>
  <!-- Lower leg -->
  <link name="BR_lower_leg">
    <inertial>
      <origin xyz="0 0 -0.15"/>
      <mass value="1.0"/>
      <inertia ixx="0.01" ixy="0.0" ixz="0.0" iyy="0.01" iyz="0.0" izz="0.01"/>
    </inertial>
    <visual>
      <geometry>
        <cylinder length="0.3" radius="0.03"/>
      </geometry>
      <material name="grey"/>
    </visual>
    <collision>
      <geometry>
        <cylinder length="0.3" radius="0.03"/>
      </geometry>
    </collision>
  </link>
  <!-- Ankle joint -->
  <joint name="BR_ankle_joint" type="continuous">
    <parent link="BR_lower_leg"/>
    <child link="BR_foot"/>
    <origin rpy="0 0 0" xyz="0 0 -0.3"/>
    <axis xyz="1 0 0"/>
    <limit effort="20" lower="-0.785" upper="0.785" velocity="2.0"/>
  </joint>
  <!-- Foot -->
  <link name="BR_foot">
    <inertial>
      <origin xyz="0 0 -0.05"/>
      <mass value="0.5"/>
      <inertia ixx="0.01" ixy="0.0" ixz="0.0" iyy="0.01" iyz="0.0" izz="0.01"/>
    </inertial>
    <visual>
      <geometry>
        <box size="0.1 0.05 0.02"/>
      </geometry>
      <material name="black"/>
    </visual>
    <collision>
      <geometry>
        <box size="0.1 0.05 0.02"/>
      </geometry>
    </collision>
  </link>
</robot>
